Workbook

Sheet Feature Definitions
A1: 영작 연습 웹앱 — 기능정의서 (Feature Definitions)
A3: IA 영역 | B3: Depth 1 | C3: Depth 2 | D3: 기능 ID | E3: 기능명 | F3: 대상 | G3: Phase | H3: 기능 정의 (목적 / Input / Output) | I3: 수익 모델
A4: 사용자 IA | B4: 비로그인 영역 | C4: 랜딩 페이지 | D4: FN-USER-001 | E4: 랜딩 페이지 | F4: 사용자 | G4: 1 | H4: 목적: 서비스 가치(단문 영작 트레이닝)를 소개하여 비로그인 방문자를 레벨 진단 또는 회원가입으로 전환시킨다. Input: 비로그인 방문자 접속. Output: 서비스 소개 콘텐츠, 레벨테스트 시작 CTA, 로그인·회원가입 링크.
A5: 사용자 IA | B5: 비로그인 영역 | C5: 레벨 진단 테스트 (비로그인 체험) | D5: FN-USER-002 | E5: 레벨 진단 테스트 | F5: 사용자 | G5: 1 | H5: 목적: 회원가입 전 10~15문항 영작으로 학습 시작 레벨을 자동 산정해 적정 난이도 세트를 추천한다. Input: 비로그인 사용자의 영작 답안 10~15문항. Output: 자동 진단 레벨, 추천 카테고리, 회원가입 유도 화면.
A6: 사용자 IA | B6: 비로그인 영역 | C6: 로그인 / 회원가입 (이메일·소셜로그인) | D6: FN-USER-003 | E6: 회원가입·로그인 | F6: 사용자 | G6: 1 | H6: 목적: 이메일 또는 소셜 로그인(OAuth) 방식으로 계정을 생성하거나 인증해 개인화 학습을 시작한다. Input: 이메일/비밀번호 또는 소셜 인증 토큰. Output: 인증 세션 발급, 초기 설정 화면(목적 선택·레벨 진단) 진입.
A7: 사용자 IA | B7: 홈 (대시보드) | C7: 오늘의 추천 문제 세트 | D7: FN-USER-004 | E7: 오늘의 추천 문제 세트 | F7: 사용자 | G7: 1 | H7: 목적: 사용자의 레벨·학습 목적·SRS 복습 대상을 고려해 당일 최적 문제 세트를 자동 구성하여 홈에서 바로 시작하게 한다. Input: 사용자 레벨, 학습 목적(회화·비즈니스·시험), ReviewSchedule(다음복습일). Output: 신규 문제 + 복습 대상이 혼합된 5~10문항 추천 세트.
A8: 사용자 IA | B8: 홈 (대시보드) | C8: 연속 학습일(스트릭)·요약 통계 | D8: FN-USER-005 | E8: 스트릭·요약 통계 | F8: 사용자 | G8: 1 | H8: 목적: 연속 학습일과 핵심 지표를 홈 대시보드에 표시해 학습 지속 동기를 강화한다. Input: Streak 테이블(연속일수·최종학습일), 최근 Submission 집계. Output: 연속 학습일 수, 총 풀이 문항 수, 최근 정답률 요약 표시.
A9: 사용자 IA | B9: 홈 (대시보드) | C9: 복습 알림 (오답·SRS 재출제 대상) | D9: FN-USER-006 | E9: 복습 알림 | F9: 사용자 | G9: 1 | H9: 목적: SRS 스케줄에 따라 당일 복습 필요 문항을 대시보드 배너와 선택적 푸시·이메일 알림으로 상기시킨다. Input: ReviewSchedule(다음복습일), 사용자 알림 설정(on/off·알림 시간대). Output: 오늘 복습할 문항 수 배지 표시, 알림 설정 시 푸시·이메일 발송.
A10: 사용자 IA | B10: 학습(연습하기) | C10: 카테고리 선택 | D10: FN-USER-007 | E10: 카테고리 선택 | F10: 사용자 | G10: 1 | H10: 목적: 학습 세션 시작 시 주제(Domain) 축과 문법포인트 축 카테고리를 조합 선택해 원하는 학습 범위로 문제를 필터링한다. Input: 카테고리 트리 — Domain 축(일상생활·여행·비즈니스·이메일·시험대비·SNS·캐주얼톡), 문법포인트 축(시제·조동사·관계사·가정법·수동태·비교급 등), 사용자 선택. Output: 선택 조건에 부합하는 문제 세트 목록.
A11: 사용자 IA | B11: 학습(연습하기) | C11: 레벨 선택 (Lv.1~10 / CEFR A1~C2) | D11: FN-USER-008 | E11: 레벨 선택 | F11: 사용자 | G11: 1 | H11: 목적: 카테고리별로 별도 관리되는 레벨(자체 Lv.1~10 + CEFR A1~C2 병기)을 선택해 문제 난이도를 조정한다. Input: 선택한 카테고리의 레벨 목록, 사용자 레벨 선택. Output: 선택 레벨에 해당하는 문제 세트 필터 적용.
A12: 사용자 IA | B12: 학습(연습하기) | C12: 문제 풀이 화면 (입력→제출→채점→해설) | D12: FN-USER-009 | E12: 문제 풀이 및 채점 | F12: 사용자 | G12: 1 | H12: 목적: 한글 프롬프트를 보고 영어 문장을 텍스트(또는 음성)로 입력·제출하면, 로컬 답안뱅크 매칭(1차)→AI 폴백(2차) 파이프라인으로 즉시 채점 결과와 해설을 제공한다. Input: 한글 프롬프트, 사용자 영작 텍스트·음성, 힌트 사용 여부(단어·문형 힌트, 사용 시 감점 가능), 실전모드(시간제한) 여부. Output: 정답·부분정답·오답 판정, 모범답안과 사용자 답 비교 하이라이트, 오류유형 태그(어순·시제·전치사·어휘선택·관사 등), 부분정답 시 더 자연스러운 대안 표현 제안, 채점 신뢰도 낮을 시 재검토 요청 버튼.
A13: 사용자 IA | B13: 학습(연습하기) | C13: 세트 완료 결과 화면 | D13: FN-USER-010 | E13: 세트 완료 결과 | F13: 사용자 | G13: 1 | H13: 목적: 한 문제 세트를 완료한 직후 세션 성과를 요약하여 학습 피드백을 제공한다. Input: 세션 내 전체 Submission 데이터(판정 결과·소요시간·오류유형). Output: 세션 점수, 정답률, 평균 소요시간, 오답 문항 리스트, 오답 복습 또는 다음 세트 시작 CTA.
A14: 사용자 IA | B14: 복습(오답노트) | C14: 전체 오답 리스트 (필터: 카테고리·레벨·오류유형·날짜) | D14: FN-USER-011 | E14: 오답노트 목록 | F14: 사용자 | G14: 1 | H14: 목적: 사용자의 오답·부분정답 Submission 전체를 저장하고 카테고리·레벨·오류유형·날짜 기준 필터로 복습 목록을 조회한다. Input: 필터 조건(카테고리·레벨·오류유형·날짜). Output: 조건에 맞는 오답 문항 목록, 각 문항의 판정 결과·오류유형·원본 제출 내용 표시.
A15: 사용자 IA | B15: 복습(오답노트) | C15: SRS 기반 "오늘 복습할 문제" | D15: FN-USER-012 | E15: SRS 복습 세트 | F15: 사용자 | G15: 2 | H15: 목적: 간격반복(SRS) 알고리즘에 따라 복습 최적 시점이 된 문항을 자동 선정하여 당일 복습 세트를 제공하고 숙련도를 갱신한다. Input: ReviewSchedule의 다음복습일·복습회차·숙련도(SRS 지수). Output: 당일 복습 대상 문항 목록, 완료 후 숙련도 갱신 및 다음 복습일 재스케줄링.
... A20: 사용자 IA | B20: 나의 기록(마이페이지) | C20: 학습 이력 (캘린더 히트맵) | D20: FN-USER-017 | E20: 학습 이력 히트맵 | F20: 사용자 | G20: 2 | H20: 목적: 날짜별 학습 활동량을 캘린더 히트맵으로 시각화하여 학습 패턴과 공백일을 직관적으로 파악하게 한다. Input: 날짜별 Submission 건수. Output: 월별·연별 캘린더 히트맵, 날짜 클릭 시 해당 일 학습 내역 표시.
A21: 사용자 IA | B21: 나의 기록(마이페이지) | C21: 설정 (알림·목표 학습량·계정관리·구독/결제) | D21: FN-USER-018 | E21: 설정 | F21: 사용자 | G21: 2 | H21: 목적: 주간 목표 문항 수·알림 시간대·알림 on/off·계정 관리(탈퇴·데이터 삭제)·구독/결제 플랜 등 개인화 설정을 제공한다. Input: 사용자의 설정 값 입력(목표량·알림 시간대·구독 플랜 선택 등). Output: 설정 저장 및 알림 스케줄·구독 플랜에 즉시 반영, 계정 삭제 시 개인정보 정책에 따른 데이터 처리. | I21: 구독형 유료 플랜
A22: 사용자 IA | B22: 커뮤니티·랭킹 (선택기능) | C22: 리더보드 (주간·전체·레벨별) | D22: FN-USER-019 | E22: 리더보드 | F22: 사용자 | G22: 3 | H22: 목적: 옵트인 방식으로 학습 성과를 닉네임 기반 순위로 표시해 경쟁 동기를 부여한다. Input: 사용자의 공개 참여(옵트인) 설정, 주간·전체 기간·레벨별 학습 지표. Output: 기간별·레벨별 순위 목록(닉네임 기반, 개인정보 최소 노출).
A23: 사용자 IA | B23: 커뮤니티·랭킹 (선택기능) | C23: 표현 공유 게시판 (우수 답안 열람) | D23: FN-USER-020 | E23: 표현 공유 게시판 | F23: 사용자 | G23: 3 | H23: 목적: 다른 학습자의 우수 답안 표현을 열람하고 자신의 정답 표현을 선택적으로 공유하는 커뮤니티 화면을 제공한다. Input: 우수 답안 공유 동의 여부, 문제별 게시판 조회. Output: 문제별 공유된 우수 답안 목록 표시.
A24: 관리자 IA | B24: 대시보드 | C24: (단독) | D24: FN-ADM-001 | E24: KPI 대시보드 | F24: 관리자 | G24: 1 | H24: 목적: 서비스 운영 핵심 지표를 한 화면에서 파악해 운영 의사결정에 활용한다. Input: 서비스 전체 이벤트 로그·사용자 데이터·문제 풀이 집계. Output: DAU/WAU, 리텐션, 문제풀이량, 가입자 수, 레벨 분포 지표 시각화.
A25: 관리자 IA | B25: 문제(콘텐츠) 관리 | C25: 문제 등록·수정·삭제 (한글 프롬프트·모범답안·허용 유사답안·해설) | D25: FN-ADM-002 | E25: 문제 CRUD | F25: 관리자 | G25: 1 | H25: 목적: 카테고리·레벨·문법포인트 조건을 설정하고 AI 생성 버튼으로 한글 프롬프트·모범답안·변형 표현·오답패턴을 일괄 생성한 뒤 검수·확정하여 저장하거나, 기존 문제를 수정·활성화·비활성화한다. Input: 카테고리·레벨·문법포인트 조건(또는 관리자 직접 입력), AI 생성 결과, 관리자 확정 액션. Output: Question + AnswerBank(출처: 관리자등록·AI자동생성)로 DB 저장, 활성화 상태 변경 및 버전 이력 기록.
A26: 관리자 IA | B26: 문제(콘텐츠) 관리 | C26: 카테고리·태그 관리 | D26: FN-ADM-003 | E26: 카테고리·태그 관리 | F26: 관리자 | G26: 2 | H26: 목적: 주제(Domain) 축(일상생활·여행·비즈니스·이메일·시험대비·SNS·캐주얼톡)과 문법포인트 축(시제·조동사·관계사·가정법·수동태·비교급 등)의 카테고리 트리를 생성·수정·삭제한다. Input: 카테고리·서브카테고리·태그 편집 입력(트리 구조). Output: 트리 구조 갱신, 연결된 문제의 태그 즉시 반영.
A27: 관리자 IA | B27: 문제(콘텐츠) 관리 | C27: 레벨 매핑 관리 | D27: FN-ADM-004 | E27: 레벨 매핑 관리 | F27: 관리자 | G27: 2 | H27: 목적: 자체 레벨(Lv.1~10)과 CEFR(A1~C2) 간의 매핑 기준을 정의하고 카테고리별 레벨 경계 및 난이도를 재조정한다. Input: 레벨-CEFR 매핑 테이블, 카테고리별 레벨 기준 편집. Output: 레벨 매핑 테이블 갱신, 문제·사용자 레벨 표시에 즉시 반영.
A28: 관리자 IA | B28: 문제(콘텐츠) 관리 | C28: 대량 업로드 (CSV·엑셀 import) | D28: FN-ADM-005 | E28: 대량 문제 업로드 | F28: 관리자 | G28: 2 | H28: 목적: CSV·Excel 파일로 조건 목록을 일괄 업로드하고 AI 일괄 생성을 실행하여 다수의 문제를 한 번에 생성·저장한다. Input: CSV·Excel 조건 파일(카테고리·레벨·문법포인트·프롬프트 등), 일괄 AI 생성 실행 액션. Output: 파일 행별로 AI 1회 호출(문제 개수에 비례한 고정 비용), 생성된 문제·AnswerBank를 검수 대기 상태로 일괄 저장.
A29: 관리자 IA | B29: 채점 로직 관리 | C29: 채점 기준(스코어링 룰) 설정 | D29: FN-ADM-006 | E29: 채점 기준 설정 | F29: 관리자 | G29: 2 | H29: 목적: 로컬 매칭 유사도 임계값·AI 폴백 신뢰도 임계값·AnswerBank 자동추가 조건·재검토 큐 전환 기준 등 채점 파이프라인 파라미터를 조정하고, 자동추가 항목(출처·사용횟수·신뢰 여부)을 관리한다. Input: 임계값 수치 편집(중복 유사도 필터·신뢰도 임계값), AnswerBank 항목별 신뢰 여부 판정, 재검토 큐의 승인·반려 액션(사용자 재검토 요청 및 저신뢰 자동판정 건 포함). Output: 파라미터 즉시 반영, AnswerBank 상태 갱신(출처 태깅·사용 카운트 트래킹), 재검토 큐 처리 완료 기록.
A30: 관리자 IA | B30: 채점 로직 관리 | C30: AI 채점 프롬프트·파라미터 관리 | D30: FN-ADM-007 | E30: AI 채점 프롬프트 관리 | F30: 관리자 | G30: 2 | H30: 목적: AI 폴백 채점 시 사용할 프롬프트 템플릿을 등록·수정하고 A/B 테스트로 채점 정확도를 검증한다. Input: 프롬프트 템플릿 텍스트, A/B 테스트 대상 버전 설정. Output: 프롬프트 버전 저장 및 채점 시 지정 버전 활용, A/B 테스트 결과 리포트.
A31: 관리자 IA | B31: 사용자 관리 | C31: 회원 목록·상태 (정지 등) | D31: FN-ADM-008 | E31: 회원 관리 | F31: 관리자 | G31: 2 | H31: 목적: 전체 회원을 조회하고 정지·탈퇴 등 계정 상태를 관리하여 서비스 운영 질을 유지한다. Input: 관리자의 회원 검색·상태 변경 액션. Output: 회원 상태(정상·정지·탈퇴) 갱신, 해당 사용자 서비스 접근 즉시 제한 또는 복원.
A32: 관리자 IA | B32: 사용자 관리 | C32: 문의·신고 처리 | D32: FN-ADM-009 | E32: 문의·신고 처리 | F32: 관리자 | G32: 2 | H32: 목적: 사용자의 문의 및 신고 티켓을 수신·처리하고 상태를 관리해 운영 이슈에 신속 대응한다. Input: 문의·신고 티켓 목록, 관리자의 처리 액션. Output: 티켓 상태 갱신(처리중·완료), 필요 시 사용자 답변 발송.
A33: 관리자 IA | B33: 통계·리포트 | C33: 문제별 오답률 (난이도 검증용) | D33: FN-ADM-010 | E33: 문제별 오답률 리포트 | F33: 관리자 | G33: 2 | H33: 목적: 각 문제의 오답률을 집계하여 지나치게 어렵거나 채점 결함이 의심되는 문제를 탐지하고 난이도 재조정·수정에 활용한다. Input: 문제별 Submission 집계 데이터. Output: 문제별 오답률 순위, 고오답률 문제 하이라이트 목록.
A34: 관리자 IA | B34: 통계·리포트 | C34: 사용자 이탈 구간 분석 | D34: FN-ADM-011 | E34: 이탈 구간 분석 | F34: 관리자 | G34: 2 | H34: 목적: 레벨·카테고리·학습 단계별 이탈 지점을 분석하여 서비스 이탈 원인을 파악하고 개선 우선순위를 도출한다. Input: 사용자 세션·Submission 이력, 이탈 이벤트 로그. Output: 이탈률 높은 레벨·카테고리·화면 구간 시각화 리포트.

Sheet Feature Specifications
A1: 영작 연습 웹앱 — 기능명세서 (Feature Specifications)
A3: 기능 ID | B3: 스펙 ID | C3: 표시순서 | D3: 기능명 | E3: 구분 | F3: 조건 / 트리거 | G3: 처리 내용 | H3: 결과 / 화면 반응 | I3: 비고
A4: FN-USER-001 | B4: FN-USER-001-MAIN-01 | C4: 1 | D4: =INDEX('Feature Definitions'!$E:$E,MATCH($A4,'Feature Definitions'!$D:$D,0)) | E4: 메인 플로우 | F4: 비로그인 방문자 URL 접속 | G4: 서비스 소개 섹션, 핵심 학습 루프(문제 노출→영작→채점→복기) 시각화, 레벨테스트 CTA 버튼, 로그인·회원가입 링크를 렌더링한다. | H4: "지금 레벨 테스트 시작하기" CTA 버튼 및 로그인·회원가입 링크 표시. 스크롤 위치에 따라 CTA 고정 노출.
A5: FN-USER-002 | B5: FN-USER-002-MAIN-01 | C5: 2 | D5: =INDEX('Feature Definitions'!$E:$E,MATCH($A5,'Feature Definitions'!$D:$D,0)) | E5: 메인 플로우 | F5: 비로그인 상태에서 레벨테스트 CTA 클릭 | G5: 10~15문항을 순차 출제하고, 마지막 문항 제출 시 정답 비율 기반으로 레벨을 자동 산정한다. | H5: 진단 결과 레벨·추천 카테고리 표시, "지금 가입하고 학습 시작하기" 회원가입 유도 화면 진입.
A6: FN-USER-002 | B6: FN-USER-002-VAL-01 | C6: 3 | D6: =INDEX('Feature Definitions'!$E:$E,MATCH($A6,'Feature Definitions'!$D:$D,0)) | E6: 유효성 검증 | F6: 미응답 문항이 있는 상태에서 '다음' 클릭 | G6: 미응답 문항 번호를 확인하고 해당 입력란을 하이라이트한다. 다음 문항으로 이동을 차단한다. | H6: (안) "답을 입력해주세요" 입력란 하단 표시. 다음 버튼 비활성 유지.
A7: FN-USER-002 | B7: FN-USER-002-BR-01 | C7: 4 | D7: =INDEX('Feature Definitions'!$E:$E,MATCH($A7,'Feature Definitions'!$D:$D,0)) | E7: 상태 분기 | F7: 진단 시작 화면에서 "스킵하고 시작하기" 선택 | G7: 레벨 진단을 건너뛰고 자가 신고 레벨 선택 화면으로 이동한다. LevelTestResult 미생성. | H7: 자가 신고 레벨 선택 드롭다운 표시 → 선택 완료 시 학습 목적 선택 화면 진행. | I7: FR-1.2
A8: FN-USER-003 | B8: FN-USER-003-MAIN-01 | C8: 5 | D8: =INDEX('Feature Definitions'!$E:$E,MATCH($A8,'Feature Definitions'!$D:$D,0)) | E8: 메인 플로우 | F8: 이메일·비밀번호 입력 후 회원가입 제출 | G8: 이메일 형식 및 비밀번호 기준(8자 이상) 검사 통과 시 계정 생성, 인증 세션 발급. | H8: 초기 설정 화면(학습 목적·레벨 진단 여부 선택) 자동 진입.
A9: FN-USER-003 | B9: FN-USER-003-MAIN-02 | C9: 6 | D9: =INDEX('Feature Definitions'!$E:$E,MATCH($A9,'Feature Definitions'!$D:$D,0)) | E9: 메인 플로우 | F9: 이메일·비밀번호 입력 후 로그인 제출 | G9: 자격증명 검사 통과 시 인증 세션 발급. | H9: 홈(대시보드) 화면으로 이동.
A10: FN-USER-003 | B10: FN-USER-003-VAL-01 | C10: 7 | D10: =INDEX('Feature Definitions'!$E:$E,MATCH($A10,'Feature Definitions'!$D:$D,0)) | E10: 유효성 검증 | F10: 이메일 형식 오류 또는 비밀번호 8자 미만 상태로 제출 | G10: 클라이언트단에서 형식 오류 감지, 서버 요청 없이 차단. | H10: (안) "올바른 이메일 형식을 입력해주세요" / "비밀번호는 8자 이상이어야 합니다" 필드 하단 즉시 표시.
A11: FN-USER-003 | B11: FN-USER-003-EXC-01 | C11: 8 | D11: =INDEX('Feature Definitions'!$E:$E,MATCH($A11,'Feature Definitions'!$D:$D,0)) | E11: 예외 처리 | F11: 이미 가입된 이메일로 신규 가입 시도 | G11: 서버에서 이메일 중복 확인 후 계정 생성 차단. | H11: (안) "이미 사용 중인 이메일입니다. 로그인하거나 다른 이메일을 사용해주세요" 안내.
A12: FN-USER-003 | B12: FN-USER-003-BR-01 | C12: 9 | D12: =INDEX('Feature Definitions'!$E:$E,MATCH($A12,'Feature Definitions'!$D:$D,0)) | E12: 상태 분기 | F12: 소셜 로그인(Google·Apple 등) 버튼 선택 | G12: OAuth 인증 팝업 실행. 인증 완료 시 소셜 계정으로 기존 계정 연동 여부 확인 후 세션 발급. 신규면 계정 자동 생성. | H12: 홈(대시보드) 이동. 최초 소셜 가입이면 학습 목적 설정 화면 진입.
A13: FN-USER-004 | B13: FN-USER-004-MAIN-01 | C13: 10 | D13: =INDEX('Feature Definitions'!$E:$E,MATCH($A13,'Feature Definitions'!$D:$D,0)) | E13: 메인 플로우 | F13: 로그인 후 홈 대시보드 진입 | G13: 사용자 레벨·학습 목적·당일 SRS 복습 대상(ReviewSchedule.다음복습일 <= 오늘)을 조회해 신규 문제 + 복습 대상 혼합 5~10문항 세트 자동 구성. | H13: "오늘의 추천 세트 N문항" 카드 및 "시작하기" CTA 표시.
A14: FN-USER-004 | B14: FN-USER-004-BR-01 | C14: 11 | D14: =INDEX('Feature Definitions'!$E:$E,MATCH($A14,'Feature Definitions'!$D:$D,0)) | E14: 상태 분기 | F14: 당일 SRS 복습 대상 문항이 없을 때 | G14: 복습 대상 없이 신규 문제만으로 세트 구성. 세트 카드 표시 방식은 동일. | H14: "오늘의 추천 세트" 카드 정상 표시. 복습/신규 구분 배지는 설정 정책에 따름.
A15: FN-USER-004 | B15: FN-USER-004-BR-02 | C15: 12 | D15: =INDEX('Feature Definitions'!$E:$E,MATCH($A15,'Feature Definitions'!$D:$D,0)) | E15: 상태 분기 | F15: 선택된 카테고리·레벨 조합의 신규 문제가 5문항 미달 | G15: 부족 카테고리를 감지하고 대안 카테고리에서 나머지 문항 보충 가능 여부 확인. | H15: (안) "이 카테고리의 새 문제가 부족합니다. 다른 카테고리도 포함하시겠습니까?" 알림 + 대안 카테고리 제안.
A16: FN-USER-005 | B16: FN-USER-005-MAIN-01 | C16: 13 | D16: =INDEX('Feature Definitions'!$E:$E,MATCH($A16,'Feature Definitions'!$D:$D,0)) | E16: 메인 플로우 | F16: 홈 대시보드 진입 | G16: Streak 테이블(연속일수·최종학습일)과 최근 Submission 집계를 조회해 스트릭·통계 카드 렌더링. | H16: 연속 학습일 수, 총 풀이 문항 수, 최근 7일 평균 정답률 표시.
A17: FN-USER-005 | B17: FN-USER-005-BR-01 | C17: 14 | D17: =INDEX('Feature Definitions'!$E:$E,MATCH($A17,'Feature Definitions'!$D:$D,0)) | E17: 상태 분기 | F17: 당일 첫 학습(문항 제출) 완료 시 | G17: Streak.연속일수 +1, Streak.최종학습일 = 오늘로 갱신. | H17: 스트릭 카드 숫자 즉시 갱신. "N일 연속 학습 중!" 텍스트 업데이트.
A18: FN-USER-005 | B18: FN-USER-005-BR-02 | C18: 15 | D18: =INDEX('Feature Definitions'!$E:$E,MATCH($A18,'Feature Definitions'!$D:$D,0)) | E18: 상태 분기 | F18: 전날 학습 이력 없이 오늘 접속 (연속 학습 공백) | G18: Streak.연속일수를 0으로 초기화, Streak.최종학습일 유지. | H18: 스트릭 카드에 0일 표시. 알림 설정 on인 경우 "스트릭이 끊겼어요. 오늘부터 다시 시작해보세요!" 알림.
A19: FN-USER-006 | B19: FN-USER-006-MAIN-01 | C19: 16 | D19: =INDEX('Feature Definitions'!$E:$E,MATCH($A19,'Feature Definitions'!$D:$D,0)) | E19: 메인 플로우 | F19: 홈 대시보드 진입 시 ReviewSchedule 조회 | G19: 다음복습일 <= 오늘인 문항 수를 집계해 N > 0이면 복습 알림 배지 렌더링. 알림 설정 on이고 발송 시간 도달 시 푸시·이메일 발송. | H19: "오늘 복습할 문제 N개" 배지 및 복습 세트 진입 CTA 표시.
... A27: FN-USER-008 | B27: FN-USER-008-BR-02 | C27: 24 | D27: =INDEX('Feature Definitions'!$E:$E,MATCH($A27,'Feature Definitions'!$D:$D,0)) | E27: 상태 분기 | F27: 선택한 레벨×카테고리 조합에 문제가 없을 때 | G27: DB 조회 결과 문제 수 = 0 확인. | H27: (안) "해당 레벨의 문제가 아직 준비 중입니다" 안내. 세트 시작 버튼 비활성화.
A28: FN-USER-009 | B28: FN-USER-009-MAIN-01 | C28: 25 | D28: =INDEX('Feature Definitions'!$E:$E,MATCH($A28,'Feature Definitions'!$D:$D,0)) | E28: 메인 플로우 | F28: 문항 화면에서 텍스트 입력 후 제출 → 로컬 매칭 성공 | G28: 사용자 입력을 해당 문제의 AnswerBank와 유사도 비교. 임계값 이상 일치 시 AI 호출 없이 즉시 정답/부분정답/오답 판정. 오류유형 태그(어순·시제·전치사·어휘선택·관사 등) 추출. Submission 저장. | H28: 판정 결과 카드, 모범답안과 사용자 답 비교 하이라이트, 오류유형 태그, 부분정답 시 "더 자연스러운 표현" 제안 표시. | I28: 1차 로컬 매칭
A29: FN-USER-009 | B29: FN-USER-009-MAIN-02 | C29: 26 | D29: =INDEX('Feature Definitions'!$E:$E,MATCH($A29,'Feature Definitions'!$D:$D,0)) | E29: 메인 플로우 | F29: 제출 → 로컬 매칭 신뢰도 임계값 미달 | G29: AI 채점 API 호출(모범답안·변형표현 목록 컨텍스트 포함, 정답 여부+오류유형 판단 요청). 정답 판정 시 해당 표현 AnswerBank에 자동 추가(출처: AI자동추가). Submission 저장. | H29: 판정 결과 동일 포맷 표시. 사용자에게 1차/2차 경로 노출 없음. | I29: 2차 AI 폴백
A30: FN-USER-009 | B30: FN-USER-009-VAL-01 | C30: 27 | D30: =INDEX('Feature Definitions'!$E:$E,MATCH($A30,'Feature Definitions'!$D:$D,0)) | E30: 유효성 검증 | F30: 텍스트 입력란이 빈 상태에서 제출 버튼 클릭 | G30: 클라이언트단에서 빈 값 감지, 서버 요청 없이 차단. | H30: (안) "영어 문장을 입력해주세요" 입력란 하단 표시. 제출 버튼 비활성 유지.
A31: FN-USER-009 | B31: FN-USER-009-BR-01 | C31: 28 | D31: =INDEX('Feature Definitions'!$E:$E,MATCH($A31,'Feature Definitions'!$D:$D,0)) | E31: 상태 분기 | F31: 힌트 사용 선택 시 | G31: 선택한 힌트 유형(단어/문형) 노출. 해당 문항 점수에서 설정된 감점 % 차감 처리. | H31: 힌트 내용 표시. 결과 화면에 "힌트 사용: -N점" 표시. | I31: FR-2.6
A32: FN-USER-009 | B32: FN-USER-009-BR-02 | C32: 29 | D32: =INDEX('Feature Definitions'!$E:$E,MATCH($A32,'Feature Definitions'!$D:$D,0)) | E32: 상태 분기 | F32: 실전모드(시간제한) 활성화 상태에서 제한 시간 초과 | G32: 타이머 만료 시 현재 입력 내용 그대로 자동 제출. 이후 채점 파이프라인 동일하게 진행. | H32: (안) "시간 초과로 자동 제출되었습니다" 안내 후 채점 결과 표시. | I32: FR-2.4
A33: FN-USER-009 | B33: FN-USER-009-BR-03 | C33: 30 | D33: =INDEX('Feature Definitions'!$E:$E,MATCH($A33,'Feature Definitions'!$D:$D,0)) | E33: 상태 분기 | F33: AI 채점 결과 신뢰도가 낮은 케이스 | G33: 판정 신뢰도 수치가 재검토 임계값 미만임을 감지. | H33: 결과 화면에 "재검토 요청" 버튼 노출. 클릭 시 해당 Submission 관리자 검수 큐로 전달. (안) "재검토 요청이 접수되었습니다" 안내. | I33: FR-3.9
A34: FN-USER-010 | B34: FN-USER-010-MAIN-01 | C34: 31 | D34: =INDEX('Feature Definitions'!$E:$E,MATCH($A34,'Feature Definitions'!$D:$D,0)) | E34: 메인 플로우 | F34: 세트 마지막 문항 제출 완료 | G34: 세션 내 전체 Submission 집계(정답 수, 오답 수, 평균 소요시간). 세션 결과 화면 렌더링. | H34: 세션 점수, 정답률, 오답 문항 리스트, "오답 복습하기" 및 "새 세트 시작" CTA 표시.
A35: FN-USER-010 | B35: FN-USER-010-BR-01 | C35: 32 | D35: =INDEX('Feature Definitions'!$E:$E,MATCH($A35,'Feature Definitions'!$D:$D,0)) | E35: 상태 분기 | F35: 정답률 100% 달성 시 | G35: 정답률 = 1.0 조건 감지. | H35: 결과 화면 상단에 (안) "완벽해요! 이 세트를 모두 맞혔습니다" 축하 메시지 추가 표시.
A36: FN-USER-010 | B36: FN-USER-010-BR-02 | C36: 33 | D36: =INDEX('Feature Definitions'!$E:$E,MATCH($A36,'Feature Definitions'!$D:$D,0)) | E36: 상태 분기 | F36: 오답이 1개 이상 있을 때 | G36: 오답 Submission 리스트 추출. | H36: 오답 문항 목록 하단에 "오답만 다시 풀기" CTA 표시. 클릭 시 오답 문항만 모아 복습 세션 시작.
A37: FN-USER-011 | B37: FN-USER-011-MAIN-01 | C37: 34 | D37: =INDEX('Feature Definitions'!$E:$E,MATCH($A37,'Feature Definitions'!$D:$D,0)) | E37: 메인 플로우 | F37: 복습 탭 진입 (필터 없음) | G37: 해당 사용자의 오답·부분정답 Submission 전체를 최신순 조회. 각 항목에 기능명·판정결과·오류유형태그·제출일 포함. | H37: 오답 목록 표시. 상단에 총 건수 "N개의 오답" 표시.
A38: FN-USER-011 | B38: FN-USER-011-BR-01 | C38: 35 | D38: =INDEX('Feature Definitions'!$E:$E,MATCH($A38,'Feature Definitions'!$D:$D,0)) | E38: 상태 분기 | F38: 필터 조건(카테고리·레벨·오류유형·날짜) 선택 | G38: 선택 조건을 AND 교집합으로 Submission 테이블에 적용해 재조회. | H38: 필터 조건에 맞는 목록으로 즉시 갱신. "N개의 오답" 건수 재표시.
A39: FN-USER-011 | B39: FN-USER-011-BR-02 | C39: 36 | D39: =INDEX('Feature Definitions'!$E:$E,MATCH($A39,'Feature Definitions'!$D:$D,0)) | E39: 상태 분기 | F39: 해당 사용자의 전체 오답·부분정답 Submission이 0건 | G39: 조회 결과 empty. | H39: (안) "아직 오답이 없습니다. 문제를 풀어보세요!" 빈 상태 화면 표시. 학습 시작 CTA 제공.
A40: FN-USER-012 | B40: FN-USER-012-MAIN-01 | C40: 37 | D40: =INDEX('Feature Definitions'!$E:$E,MATCH($A40,'Feature Definitions'!$D:$D,0)) | E40: 메인 플로우 | F40: "오늘 복습할 문제" CTA 클릭 | G40: ReviewSchedule에서 다음복습일 <= 오늘인 문항 선정. 일반 문제 풀이 화면과 동일한 방식으로 순차 출제·채점. | H40: 복습 세트 풀이 화면 진입. 풀이·채점 동작은 FN-USER-009와 동일.
A41: FN-USER-012 | B41: FN-USER-012-BR-01 | C41: 38 | D41: =INDEX('Feature Definitions'!$E:$E,MATCH($A41,'Feature Definitions'!$D:$D,0)) | E41: 상태 분기 | F41: 복습 문항 정답 처리 완료 | G41: ReviewSchedule.복습회차 +1, 숙련도 상승, 다음복습일 = 오늘 + SRS 알고리즘 산출 간격. | H41: (안) "잘했어요! 다음 복습은 N일 후입니다" 문항별 결과 표시.
A42: FN-USER-012 | B42: FN-USER-012-BR-02 | C42: 39 | D42: =INDEX('Feature Definitions'!$E:$E,MATCH($A42,'Feature Definitions'!$D:$D,0)) | E42: 상태 분기 | F42: 복습 문항 오답 처리 | G42: ReviewSchedule.복습회차 리셋(또는 감소), 숙련도 하락, 다음복습일 = 오늘 + 단축 간격. | H42: (안) "다시 한 번 도전해봐요. N일 후 다시 출제됩니다" 표시.
A43: FN-USER-012 | B43: FN-USER-012-BR-03 | C43: 40 | D43: =INDEX('Feature Definitions'!$E:$E,MATCH($A43,'Feature Definitions'!$D:$D,0)) | E43: 상태 분기 | F43: 당일 복습 대상 문항 0개 | G43: ReviewSchedule 조회 결과 empty. | H43: (안) "오늘 복습할 문제가 없습니다. 새 문제를 연습해보세요!" 빈 상태 화면. 새 문제 시작 CTA 표시.
A44: FN-USER-013 | B44: FN-USER-013-MAIN-01 | C44: 41 | D44: =INDEX('Feature Definitions'!$E:$E,MATCH($A44,'Feature Definitions'!$D:$D,0)) | E44: 메인 플로우 | F44: 채점 결과 화면 또는 오답노트에서 북마크 아이콘 탭 | G44: Bookmark 테이블에 (userId, questionId) 저장. | H44: 북마크 아이콘 활성(채워진) 상태로 즉시 전환.
A45: FN-USER-013 | B45: FN-USER-013-MAIN-02 | C45: 42 | D45: =INDEX('Feature Definitions'!$E:$E,MATCH($A45,'Feature Definitions'!$D:$D,0)) | E45: 메인 플로우 | F45: 복습 탭 또는 마이페이지에서 즐겨찾기 필터 선택 | G45: Bookmark 테이블에서 해당 userId의 questionId 목록 조회 후 문항 데이터 조합. | H45: 즐겨찾기된 문항 목록 표시. 건수 "N개의 즐겨찾기" 표시.
... A57: FN-USER-018 | B57: FN-USER-018-VAL-01 | C57: 54 | D57: =INDEX('Feature Definitions'!$E:$E,MATCH($A57,'Feature Definitions'!$D:$D,0)) | E57: 유효성 검증 | F57: 주간 목표 문항 수를 0 이하 또는 빈값으로 저장 시도 | G57: 저장 전 입력값 범위 검사. 1 미만이면 저장 차단. | H57: (안) "목표 문항 수는 1 이상이어야 합니다" 필드 하단 표시. 저장 버튼 비활성.
A58: FN-USER-018 | B58: FN-USER-018-BR-01 | C58: 55 | D58: =INDEX('Feature Definitions'!$E:$E,MATCH($A58,'Feature Definitions'!$D:$D,0)) | E58: 상태 분기 | F58: 계정 탈퇴 선택 | G58: 탈퇴 확인 모달 표시. 확인 시 개인정보 삭제·익명화 처리(개인정보 정책 준수). | H58: (안) "탈퇴 시 모든 학습 데이터가 삭제됩니다. 정말 탈퇴하시겠습니까?" 모달. 확인 → 탈퇴 처리 후 랜딩 페이지 이동. | I58: FR-6.3
A59: FN-USER-018 | B59: FN-USER-018-BR-02 | C59: 56 | D59: =INDEX('Feature Definitions'!$E:$E,MATCH($A59,'Feature Definitions'!$D:$D,0)) | E59: 상태 분기 | F59: 무료 사용자가 유료 전용 설정 항목 접근 | G59: 사용자 구독 상태 확인 후 무료 플랜 감지. | H59: (안) "이 기능은 유료 플랜 사용자만 이용할 수 있습니다. 업그레이드하시겠습니까?" 안내. 확인 시 구독 화면 진입. | I59: 구독형 유료 플랜
...
